[2024-12-21T20:26:28.255+0000] {taskinstance.py:1165} INFO - Dependencies all met for <TaskInstance: 6.1-monitoreando.tarea5 scheduled__2022-07-07T00:00:00+00:00 [queued]>
[2024-12-21T20:26:28.605+0000] {taskinstance.py:1165} INFO - Dependencies all met for <TaskInstance: 6.1-monitoreando.tarea5 scheduled__2022-07-07T00:00:00+00:00 [queued]>
[2024-12-21T20:26:28.610+0000] {taskinstance.py:1362} INFO - 
--------------------------------------------------------------------------------
[2024-12-21T20:26:28.623+0000] {taskinstance.py:1363} INFO - Starting attempt 1 of 1
[2024-12-21T20:26:28.625+0000] {taskinstance.py:1364} INFO - 
--------------------------------------------------------------------------------
[2024-12-21T20:26:28.782+0000] {taskinstance.py:1383} INFO - Executing <Task(PythonOperator): tarea5> on 2022-07-07 00:00:00+00:00
[2024-12-21T20:26:28.862+0000] {standard_task_runner.py:55} INFO - Started process 4651 to run task
[2024-12-21T20:26:28.936+0000] {standard_task_runner.py:82} INFO - Running: ['***', 'tasks', 'run', '6.1-monitoreando', 'tarea5', 'scheduled__2022-07-07T00:00:00+00:00', '--job-id', '2394', '--raw', '--subdir', 'DAGS_FOLDER/6.1-monitoring.py', '--cfg-path', '/tmp/tmp4ywf8tu0']
[2024-12-21T20:26:28.952+0000] {standard_task_runner.py:83} INFO - Job 2394: Subtask tarea5
[2024-12-21T20:26:30.696+0000] {task_command.py:376} INFO - Running <TaskInstance: 6.1-monitoreando.tarea5 scheduled__2022-07-07T00:00:00+00:00 [running]> on host a39b43f32cb0
[2024-12-21T20:26:31.839+0000] {taskinstance.py:1592} INFO - Exporting the following env vars:
AIRFLOW_CTX_DAG_OWNER=***
AIRFLOW_CTX_DAG_ID=6.1-monitoreando
AIRFLOW_CTX_TASK_ID=tarea5
AIRFLOW_CTX_EXECUTION_DATE=2022-07-07T00:00:00+00:00
AIRFLOW_CTX_TRY_NUMBER=1
AIRFLOW_CTX_DAG_RUN_ID=scheduled__2022-07-07T00:00:00+00:00
[2024-12-21T20:26:31.870+0000] {taskinstance.py:1851} ERROR - Task failed with exception
Traceback (most recent call last):
  File "/home/airflow/.local/lib/python3.7/site-packages/airflow/operators/python.py", line 175, in execute
    return_value = self.execute_callable()
  File "/home/airflow/.local/lib/python3.7/site-packages/airflow/operators/python.py", line 193, in execute_callable
    return self.python_callable(*self.op_args, **self.op_kwargs)
  File "/opt/airflow/dags/6.1-monitoring.py", line 7, in myFunction
    raise Exception
Exception
[2024-12-21T20:26:31.945+0000] {taskinstance.py:1406} INFO - Marking task as FAILED. dag_id=6.1-monitoreando, task_id=tarea5, execution_date=20220707T000000, start_date=20241221T202628, end_date=20241221T202631
[2024-12-21T20:26:32.037+0000] {standard_task_runner.py:105} ERROR - Failed to execute job 2394 for task tarea5 (; 4651)
[2024-12-21T20:26:32.138+0000] {local_task_job.py:164} INFO - Task exited with return code 1
[2024-12-21T20:26:32.649+0000] {local_task_job.py:273} INFO - 0 downstream tasks scheduled from follow-on schedule check
