[2024-12-21T20:26:30.644+0000] {taskinstance.py:1165} INFO - Dependencies all met for <TaskInstance: 6.1-monitoreando.tarea5 scheduled__2022-07-03T00:00:00+00:00 [queued]>
[2024-12-21T20:26:30.842+0000] {taskinstance.py:1165} INFO - Dependencies all met for <TaskInstance: 6.1-monitoreando.tarea5 scheduled__2022-07-03T00:00:00+00:00 [queued]>
[2024-12-21T20:26:30.851+0000] {taskinstance.py:1362} INFO - 
--------------------------------------------------------------------------------
[2024-12-21T20:26:30.864+0000] {taskinstance.py:1363} INFO - Starting attempt 1 of 1
[2024-12-21T20:26:30.870+0000] {taskinstance.py:1364} INFO - 
--------------------------------------------------------------------------------
[2024-12-21T20:26:31.218+0000] {taskinstance.py:1383} INFO - Executing <Task(PythonOperator): tarea5> on 2022-07-03 00:00:00+00:00
[2024-12-21T20:26:31.284+0000] {standard_task_runner.py:55} INFO - Started process 4660 to run task
[2024-12-21T20:26:31.511+0000] {standard_task_runner.py:82} INFO - Running: ['***', 'tasks', 'run', '6.1-monitoreando', 'tarea5', 'scheduled__2022-07-03T00:00:00+00:00', '--job-id', '2397', '--raw', '--subdir', 'DAGS_FOLDER/6.1-monitoring.py', '--cfg-path', '/tmp/tmp6clqwb8o']
[2024-12-21T20:26:31.556+0000] {standard_task_runner.py:83} INFO - Job 2397: Subtask tarea5
[2024-12-21T20:26:32.032+0000] {task_command.py:376} INFO - Running <TaskInstance: 6.1-monitoreando.tarea5 scheduled__2022-07-03T00:00:00+00:00 [running]> on host a39b43f32cb0
[2024-12-21T20:26:32.892+0000] {taskinstance.py:1592} INFO - Exporting the following env vars:
AIRFLOW_CTX_DAG_OWNER=***
AIRFLOW_CTX_DAG_ID=6.1-monitoreando
AIRFLOW_CTX_TASK_ID=tarea5
AIRFLOW_CTX_EXECUTION_DATE=2022-07-03T00:00:00+00:00
AIRFLOW_CTX_TRY_NUMBER=1
AIRFLOW_CTX_DAG_RUN_ID=scheduled__2022-07-03T00:00:00+00:00
[2024-12-21T20:26:32.925+0000] {taskinstance.py:1851} ERROR - Task failed with exception
Traceback (most recent call last):
  File "/home/airflow/.local/lib/python3.7/site-packages/airflow/operators/python.py", line 175, in execute
    return_value = self.execute_callable()
  File "/home/airflow/.local/lib/python3.7/site-packages/airflow/operators/python.py", line 193, in execute_callable
    return self.python_callable(*self.op_args, **self.op_kwargs)
  File "/opt/airflow/dags/6.1-monitoring.py", line 7, in myFunction
    raise Exception
Exception
[2024-12-21T20:26:33.316+0000] {taskinstance.py:1406} INFO - Marking task as FAILED. dag_id=6.1-monitoreando, task_id=tarea5, execution_date=20220703T000000, start_date=20241221T202630, end_date=20241221T202633
[2024-12-21T20:26:33.774+0000] {standard_task_runner.py:105} ERROR - Failed to execute job 2397 for task tarea5 (; 4660)
[2024-12-21T20:26:34.208+0000] {local_task_job.py:164} INFO - Task exited with return code 1
[2024-12-21T20:26:35.235+0000] {local_task_job.py:273} INFO - 0 downstream tasks scheduled from follow-on schedule check
